<?xml version="1.0" ?>
<!-- =================================================================================== -->
<!-- |    This document was autogenerated by xacro from pipebot.xacro                  | -->
<!-- |    EDITING THIS FILE BY HAND IS NOT RECOMMENDED                                 | -->
<!-- =================================================================================== -->
<robot name="pipebot">
  <material name="silver">
    <color rgba="0.700 0.700 0.700 1.000"/>
  </material>
  <transmission name="FR_hip_joint_tran">
    <type>transmission_interface/SimpleTransmission</type>
    <joint name="FR_hip_joint">
      <hardwareInterface>hardware_interface/EffortJointInterface</hardwareInterface>
    </joint>
    <actuator name="FR_hip_joint_actr">
      <hardwareInterface>hardware_interface/EffortJointInterface</hardwareInterface>
      <mechanicalReduction>1</mechanicalReduction>
    </actuator>
  </transmission>
  <transmission name="FL_hip_joint_tran">
    <type>transmission_interface/SimpleTransmission</type>
    <joint name="FL_hip_joint">
      <hardwareInterface>hardware_interface/EffortJointInterface</hardwareInterface>
    </joint>
    <actuator name="FL_hip_joint_actr">
      <hardwareInterface>hardware_interface/EffortJointInterface</hardwareInterface>
      <mechanicalReduction>1</mechanicalReduction>
    </actuator>
  </transmission>
  <transmission name="BR_hip_joint_tran">
    <type>transmission_interface/SimpleTransmission</type>
    <joint name="BR_hip_joint">
      <hardwareInterface>hardware_interface/EffortJointInterface</hardwareInterface>
    </joint>
    <actuator name="BR_hip_joint_actr">
      <hardwareInterface>hardware_interface/EffortJointInterface</hardwareInterface>
      <mechanicalReduction>1</mechanicalReduction>
    </actuator>
  </transmission>
  <transmission name="BL_hip_joint_tran">
    <type>transmission_interface/SimpleTransmission</type>
    <joint name="BL_hip_joint">
      <hardwareInterface>hardware_interface/EffortJointInterface</hardwareInterface>
    </joint>
    <actuator name="BL_hip_joint_actr">
      <hardwareInterface>hardware_interface/EffortJointInterface</hardwareInterface>
      <mechanicalReduction>1</mechanicalReduction>
    </actuator>
  </transmission>
  <transmission name="FR_thigh_joint_tran">
    <type>transmission_interface/SimpleTransmission</type>
    <joint name="FR_thigh_joint">
      <hardwareInterface>hardware_interface/EffortJointInterface</hardwareInterface>
    </joint>
    <actuator name="FR_thigh_joint_actr">
      <hardwareInterface>hardware_interface/EffortJointInterface</hardwareInterface>
      <mechanicalReduction>1</mechanicalReduction>
    </actuator>
  </transmission>
  <transmission name="FL_thigh_joint_tran">
    <type>transmission_interface/SimpleTransmission</type>
    <joint name="FL_thigh_joint">
      <hardwareInterface>hardware_interface/EffortJointInterface</hardwareInterface>
    </joint>
    <actuator name="FL_thigh_joint_actr">
      <hardwareInterface>hardware_interface/EffortJointInterface</hardwareInterface>
      <mechanicalReduction>1</mechanicalReduction>
    </actuator>
  </transmission>
  <transmission name="BR_thigh_joint_tran">
    <type>transmission_interface/SimpleTransmission</type>
    <joint name="BR_thigh_joint">
      <hardwareInterface>hardware_interface/EffortJointInterface</hardwareInterface>
    </joint>
    <actuator name="BR_thigh_joint_actr">
      <hardwareInterface>hardware_interface/EffortJointInterface</hardwareInterface>
      <mechanicalReduction>1</mechanicalReduction>
    </actuator>
  </transmission>
  <transmission name="BL_thigh_joint_tran">
    <type>transmission_interface/SimpleTransmission</type>
    <joint name="BL_thigh_joint">
      <hardwareInterface>hardware_interface/EffortJointInterface</hardwareInterface>
    </joint>
    <actuator name="BL_thigh_joint_actr">
      <hardwareInterface>hardware_interface/EffortJointInterface</hardwareInterface>
      <mechanicalReduction>1</mechanicalReduction>
    </actuator>
  </transmission>
  <transmission name="FR_calf_joint_tran">
    <type>transmission_interface/SimpleTransmission</type>
    <joint name="FR_calf_joint">
      <hardwareInterface>hardware_interface/EffortJointInterface</hardwareInterface>
    </joint>
    <actuator name="FR_calf_joint_actr">
      <hardwareInterface>hardware_interface/EffortJointInterface</hardwareInterface>
      <mechanicalReduction>1</mechanicalReduction>
    </actuator>
  </transmission>
  <transmission name="FL_calf_joint_tran">
    <type>transmission_interface/SimpleTransmission</type>
    <joint name="FL_calf_joint">
      <hardwareInterface>hardware_interface/EffortJointInterface</hardwareInterface>
    </joint>
    <actuator name="FL_calf_joint_actr">
      <hardwareInterface>hardware_interface/EffortJointInterface</hardwareInterface>
      <mechanicalReduction>1</mechanicalReduction>
    </actuator>
  </transmission>
  <transmission name="BR_calf_joint_tran">
    <type>transmission_interface/SimpleTransmission</type>
    <joint name="BR_calf_joint">
      <hardwareInterface>hardware_interface/EffortJointInterface</hardwareInterface>
    </joint>
    <actuator name="BR_calf_joint_actr">
      <hardwareInterface>hardware_interface/EffortJointInterface</hardwareInterface>
      <mechanicalReduction>1</mechanicalReduction>
    </actuator>
  </transmission>
  <transmission name="BL_calf_joint_tran">
    <type>transmission_interface/SimpleTransmission</type>
    <joint name="BL_calf_joint">
      <hardwareInterface>hardware_interface/EffortJointInterface</hardwareInterface>
    </joint>
    <actuator name="BL_calf_joint_actr">
      <hardwareInterface>hardware_interface/EffortJointInterface</hardwareInterface>
      <mechanicalReduction>1</mechanicalReduction>
    </actuator>
  </transmission>

  <transmission name="arm_1_joint_tran">
    <type>transmission_interface/SimpleTransmission</type>
    <joint name="arm_1_joint">
      <hardwareInterface>hardware_interface/EffortJointInterface</hardwareInterface>
    </joint>
    <actuator name="arm_1_joint_actr">
      <hardwareInterface>hardware_interface/EffortJointInterface</hardwareInterface>
      <mechanicalReduction>1</mechanicalReduction>
    </actuator>
  </transmission>
  <transmission name="arm_2_joint_tran">
    <type>transmission_interface/SimpleTransmission</type>
    <joint name="arm_2_joint">
      <hardwareInterface>hardware_interface/EffortJointInterface</hardwareInterface>
    </joint>
    <actuator name="arm_2_joint_actr">
      <hardwareInterface>hardware_interface/EffortJointInterface</hardwareInterface>
      <mechanicalReduction>1</mechanicalReduction>
    </actuator>
  </transmission>
  <transmission name="arm_3_joint_tran">
    <type>transmission_interface/SimpleTransmission</type>
    <joint name="arm_3_joint">
      <hardwareInterface>hardware_interface/EffortJointInterface</hardwareInterface>
    </joint>
    <actuator name="arm_3_joint_actr">
      <hardwareInterface>hardware_interface/EffortJointInterface</hardwareInterface>
      <mechanicalReduction>1</mechanicalReduction>
    </actuator>
  </transmission>
  <transmission name="arm_4_joint_tran">
    <type>transmission_interface/SimpleTransmission</type>
    <joint name="arm_4_joint">
      <hardwareInterface>hardware_interface/EffortJointInterface</hardwareInterface>
    </joint>
    <actuator name="arm_4_joint_actr">
      <hardwareInterface>hardware_interface/EffortJointInterface</hardwareInterface>
      <mechanicalReduction>1</mechanicalReduction>
    </actuator>
  </transmission>
  <transmission name="arm_5_joint_tran">
    <type>transmission_interface/SimpleTransmission</type>
    <joint name="arm_5_joint">
      <hardwareInterface>hardware_interface/EffortJointInterface</hardwareInterface>
    </joint>
    <actuator name="arm_5_joint_actr">
      <hardwareInterface>hardware_interface/EffortJointInterface</hardwareInterface>
      <mechanicalReduction>1</mechanicalReduction>
    </actuator>
  </transmission>
  <transmission name="arm_6_joint_tran">
    <type>transmission_interface/SimpleTransmission</type>
    <joint name="arm_6_joint">
      <hardwareInterface>hardware_interface/EffortJointInterface</hardwareInterface>
    </joint>
    <actuator name="arm_6_joint_actr">
      <hardwareInterface>hardware_interface/EffortJointInterface</hardwareInterface>
      <mechanicalReduction>1</mechanicalReduction>
    </actuator>
  </transmission>

  <transmission name="finger_joint_trans">
    <type>transmission_interface/SimpleTransmission</type>
    <joint name="finger_joint">
      <hardwareInterface>hardware_interface/PositionJointInterface</hardwareInterface>
    </joint>
    <actuator name="finger_joint_motor">
      <mechanicalReduction>1</mechanicalReduction>
    </actuator>
  </transmission>
  <transmission name="left_inner_knuckle_joint_trans">
    <type>transmission_interface/SimpleTransmission</type>
    <joint name="left_inner_knuckle_joint">
      <hardwareInterface>hardware_interface/PositionJointInterface</hardwareInterface>
    </joint>
    <actuator name="left_inner_knuckle_joint_motor">
      <mechanicalReduction>1</mechanicalReduction>
    </actuator>
  </transmission>
  <transmission name="left_inner_finger_joint_trans">
    <type>transmission_interface/SimpleTransmission</type>
    <joint name="left_inner_finger_joint">
      <hardwareInterface>hardware_interface/PositionJointInterface</hardwareInterface>
    </joint>
    <actuator name="left_inner_finger_joint_motor">
      <mechanicalReduction>1</mechanicalReduction>
    </actuator>
  </transmission>
  <transmission name="right_outer_knuckle_joint_trans">
    <type>transmission_interface/SimpleTransmission</type>
    <joint name="right_outer_knuckle_joint">
      <hardwareInterface>hardware_interface/PositionJointInterface</hardwareInterface>
    </joint>
    <actuator name="right_outer_knuckle_joint_motor">
      <mechanicalReduction>1</mechanicalReduction>
    </actuator>
  </transmission>
  <transmission name="right_inner_knuckle_joint_trans">
    <type>transmission_interface/SimpleTransmission</type>
    <joint name="right_inner_knuckle_joint">
      <hardwareInterface>hardware_interface/PositionJointInterface</hardwareInterface>
    </joint>
    <actuator name="right_inner_knuckle_joint_motor">
      <mechanicalReduction>1</mechanicalReduction>
    </actuator>
  </transmission>
  <transmission name="right_inner_finger_joint_trans">
    <type>transmission_interface/SimpleTransmission</type>
    <joint name="right_inner_finger_joint">
      <hardwareInterface>hardware_interface/PositionJointInterface</hardwareInterface>
    </joint>
    <actuator name="right_inner_finger_joint_motor">
      <mechanicalReduction>1</mechanicalReduction>
    </actuator>
  </transmission>



  <gazebo>
    <plugin filename="libgazebo_ros_control.so" name="control">
      <legacyModeNS>true</legacyModeNS>
    </plugin>
  </gazebo>
  <gazebo reference="base_link">
    <material>Gazebo/DarkGrey</material>
 <!--    <mu1>0.2</mu1>
    <mu2>0.2</mu2> -->
    <gravity>true</gravity>
  </gazebo>
  <gazebo reference="FR_hip_1">
    <material>Gazebo/Grey</material>
    <!-- <mu1>0.2</mu1>
    <mu2>0.2</mu2> -->
  </gazebo>
  <gazebo reference="FL_hip_1">
    <material>Gazebo/Grey</material>
<!--     <mu1>0.2</mu1>
    <mu2>0.2</mu2> -->
  </gazebo>
  <gazebo reference="BR_hip_1">
    <material>Gazebo/Grey</material>
    <!-- <mu1>0.2</mu1>
    <mu2>0.2</mu2> -->
  </gazebo>
  <gazebo reference="BL_hip_2">
    <material>Gazebo/Grey</material>
    <!-- <mu1>0.2</mu1>
    <mu2>0.2</mu2> -->
  </gazebo>
  <gazebo reference="FR_thigh_2">
    <material>Gazebo/DarkGrey</material>
    <!-- <mu1>0.2</mu1>
    <mu2>0.2</mu2> -->
  </gazebo>
  <gazebo reference="FL_thigh_1">
    <material>Gazebo/DarkGrey</material>
    <!-- <mu1>0.2</mu1>
    <mu2>0.2</mu2> -->
  </gazebo>
  <gazebo reference="BR_thigh_1">
    <material>Gazebo/DarkGrey</material>
    <!-- <mu1>0.2</mu1>
    <mu2>0.2</mu2> -->
  </gazebo>
  <gazebo reference="BL_thigh_1">
    <material>Gazebo/DarkGrey</material>
    <!-- <mu1>0.2</mu1>
    <mu2>0.2</mu2> -->
  </gazebo>
  <gazebo reference="FR_calf_2">
    <material>Gazebo/DarkGrey</material>
    <!-- <mu1>0.2</mu1>
    <mu2>0.2</mu2> -->
  </gazebo>
  <gazebo reference="FL_calf_1">
    <material>Gazebo/DarkGrey</material>
    <!-- <mu1>0.2</mu1>
    <mu2>0.2</mu2> -->
  </gazebo>
  <gazebo reference="BR_calf_1">
    <material>Gazebo/DarkGrey</material>
    <!-- <mu1>0.2</mu1>
    <mu2>0.2</mu2> -->
  </gazebo>
  <gazebo reference="BL_calf_1">
    <material>Gazebo/DarkGrey</material>
    <!-- <mu1>0.2</mu1>
    <mu2>0.2</mu2> -->
  </gazebo>
  <gazebo reference="ARM_1_1">
    <material>Gazebo/Grey</material>
      <mu1>10.0</mu1>
      <mu2>10.0</mu2>
      <kp>1000000.0</kp>
      <kd>1000.0</kd>
      <minDepth>0.01</minDepth>
      <maxVel>1.0</maxVel>
  </gazebo>
  <gazebo reference="ARM_2_1">
    <material>Gazebo/DarkGrey</material>
      <mu1>10.0</mu1>
      <mu2>10.0</mu2>
      <kp>1000000.0</kp>
      <kd>1000.0</kd>
      <minDepth>0.01</minDepth>
      <maxVel>1.0</maxVel>
  </gazebo>
  <gazebo reference="ARM_3_1">
    <material>Gazebo/DarkGrey</material>
      <mu1>10.0</mu1>
      <mu2>10.0</mu2>
      <kp>1000000.0</kp>
      <kd>1000.0</kd>
      <minDepth>0.01</minDepth>
      <maxVel>1.0</maxVel>
  </gazebo>
  <gazebo reference="ARM_4_1">
    <material>Gazebo/DarkGrey</material>
      <mu1>10.0</mu1>
      <mu2>10.0</mu2>
      <kp>1000000.0</kp>
      <kd>1000.0</kd>
      <minDepth>0.01</minDepth>
      <maxVel>1.0</maxVel>
  </gazebo>
  <gazebo reference="ARM_5_1">
    <material>Gazebo/DarkGrey</material>
      <mu1>10.0</mu1>
      <mu2>10.0</mu2>
      <kp>1000000.0</kp>
      <kd>1000.0</kd>
      <minDepth>0.01</minDepth>
      <maxVel>1.0</maxVel>
  </gazebo>
  <gazebo reference="ARM_6_1">
    <material>Gazebo/DarkGrey</material>
<!--     <mu1>0.2</mu1>
    <mu2>0.2</mu2> -->
      <mu1>10.0</mu1>
      <mu2>10.0</mu2>
      <kp>1000000.0</kp>
      <kd>1000.0</kd>
      <minDepth>0.01</minDepth>
      <maxVel>1.0</maxVel>
  </gazebo>
  <gazebo reference="FL_foot_1">
    <material>Gazebo/Black</material>
      <mu1>10.0</mu1>
      <mu2>10.0</mu2>
      <kp>1000000.0</kp>
      <kd>1000.0</kd>
      <minDepth>0.01</minDepth>
      <maxVel>1.0</maxVel>
  </gazebo>
  <gazebo reference="FR_foot_1">
    <material>Gazebo/Black</material>
      <mu1>10.0</mu1>
      <mu2>10.0</mu2>
      <kp>1000000.0</kp>
      <kd>1000.0</kd>
      <minDepth>0.01</minDepth>
      <maxVel>1.0</maxVel>
  </gazebo>
  <gazebo reference="BR_foot_4">
    <material>Gazebo/Black</material>
      <mu1>10.0</mu1>
      <mu2>10.0</mu2>
      <kp>1000000.0</kp>
      <kd>1000.0</kd>
      <minDepth>0.01</minDepth>
      <maxVel>1.0</maxVel>
  </gazebo>
  <gazebo reference="BL_foot_1">    
    <material>Gazebo/Black</material>
      <mu1>10.0</mu1>
      <mu2>10.0</mu2>
      <kp>1000000.0</kp>
      <kd>1000.0</kd>
      <minDepth>0.01</minDepth>
      <maxVel>1.0</maxVel>
  </gazebo>
  

  <gazebo reference="robotiq_arg2f_base_link">    
    <material>Gazebo/Grey</material>
  </gazebo>
  <gazebo reference="left_outer_knuckle">    
    <material>Gazebo/White</material>
  </gazebo>
  <gazebo reference="left_outer_finger">    
    <material>Gazebo/DarkGrey</material>
  </gazebo>
  <gazebo reference="left_inner_finger">    
    <material>Gazebo/DarkGrey</material>
  </gazebo>
  <gazebo reference="left_inner_finger_pad">    
    <material>Gazebo/White</material>
      <mu1>1000.0</mu1>
      <mu2>1000.0</mu2>
      <kp>1000000000.0</kp>
      <kd>100000000.0</kd>
      <slip1>0</slip1>
      <slip2>0</slip2>
      <minDepth>0.001</minDepth>
      <maxVel>0.0</maxVel>
      <torsional>
        <ode>
            <coefficient>1000</coefficient>
            <slip>0</slip>
        </ode>
      </torsional>
  </gazebo>
  <gazebo reference="left_inner_knuckle">    
    <material>Gazebo/DarkGrey</material>
  </gazebo>
  <gazebo reference="right_outer_knuckle">    
    <material>Gazebo/White</material>
  </gazebo>
  <gazebo reference="right_outer_finger">    
    <material>Gazebo/DarkGrey</material>
  </gazebo>
  <gazebo reference="right_inner_finger">    
    <material>Gazebo/DarkGrey</material>
  </gazebo>
  <gazebo reference="right_inner_finger_pad">    
    <material>Gazebo/White</material>
      <mu1>1000.0</mu1>
      <mu2>1000.0</mu2>
      <kp>1000000000.0</kp>
      <kd>100000000.0</kd>
      <slip1>0</slip1>
      <slip2>0</slip2>
      <minDepth>0.001</minDepth>
      <maxVel>0.0</maxVel>
      <torsional>
        <ode>
            <coefficient>1000</coefficient>
            <slip>0</slip>
        </ode>
      </torsional>
  </gazebo>
  <gazebo reference="right_inner_knuckle">    
    <material>Gazebo/DarkGrey</material>
  </gazebo>


  <link name="base_link">
    <inertial>
      <origin rpy="0 0 0" xyz="0.0033827602101410043 -0.00027510616293287325 0.07066379377055013"/>
      <mass value="14.029718208807811"/>      
      <inertia ixx="0.085792" ixy="-4e-06" ixz="-0.005638" iyy="0.321558" iyz="-0.0" izz="0.365464"/>
    </inertial>
    <visual>
      <origin rpy="0 0 0" xyz="0 0 0"/>
      <geometry>
        <mesh filename="package://pipebot_config/meshes/base_link.stl" scale="0.001 0.001 0.001"/>
      </geometry>
      <material name="silver"/>
    </visual>
    <collision>
      <origin rpy="0 0 0" xyz="0 0 0.07"/>
      <geometry>
        <!-- <mesh filename="package://pipebot_config/meshes/base_link.stl" scale="0.001 0.001 0.001"/> -->
        <box size="0.532 0.285 0.135" />
      </geometry>
    </collision>
  </link>
  <link name="FR_hip_1">
    <inertial>
      <origin rpy="0 0 0" xyz="0.05534495479566107 -0.008820712971960562 -3.2335245592207684e-15"/>
      <mass value="0.5405625696384098"/>
      <inertia ixx="0.000528" ixy="-2e-06" ixz="-0.0" iyy="0.000646" iyz="-0.0" izz="0.000551"/>
    </inertial>
    <visual>
      <origin rpy="0 0 0" xyz="-0.0897 0.110275 -0.0675"/>
      <geometry>
        <mesh filename="package://pipebot_config/meshes/FR_hip_1.stl" scale="0.001 0.001 0.001"/>
      </geometry>
      <material name="silver"/>
    </visual>
 <!--    <collision>
      <origin rpy="0 0 0" xyz="-0.0897 0.110275 -0.0675"/>
      <geometry>
        <mesh filename="package://pipebot_config/meshes/FR_hip_1.stl" scale="0.001 0.001 0.001"/>
      </geometry>
    </collision> -->
  </link>
  <link name="FL_hip_1">
    <inertial>
      <origin rpy="0 0 0" xyz="0.05534495479566112 0.008821436558665019 3.066991105526995e-15"/>
      <mass value="0.5405625696384098"/>
      <inertia ixx="0.000528" ixy="2e-06" ixz="0.0" iyy="0.000646" iyz="-0.0" izz="0.000551"/>
    </inertial>
    <visual>
      <origin rpy="0 0 0" xyz="-0.0897 -0.109725 -0.0675"/>
      <geometry>
        <mesh filename="package://pipebot_config/meshes/FL_hip_1.stl" scale="0.001 0.001 0.001"/>
      </geometry>
      <material name="silver"/>
    </visual>
 <!--    <collision>
      <origin rpy="0 0 0" xyz="-0.0897 -0.109725 -0.0675"/>
      <geometry>
        <mesh filename="package://pipebot_config/meshes/FL_hip_1.stl" scale="0.001 0.001 0.001"/>
      </geometry>
    </collision> -->
  </link>
  <link name="BR_hip_1">
    <inertial>
      <origin rpy="0 0 0" xyz="-0.05534530530947 -0.00882071297196084 2.9837243786801082e-15"/>
      <mass value="0.5405625696384098"/>
      <inertia ixx="0.000528" ixy="2e-06" ixz="-0.0" iyy="0.000646" iyz="0.0" izz="0.000551"/>
    </inertial>
    <visual>
      <origin rpy="0 0 0" xyz="0.0903 0.110275 -0.0675"/>
      <geometry>
        <mesh filename="package://pipebot_config/meshes/BR_hip_1.stl" scale="0.001 0.001 0.001"/>
      </geometry>
      <material name="silver"/>
    </visual>
   <!--  <collision>
      <origin rpy="0 0 0" xyz="0.0903 0.110275 -0.0675"/>
      <geometry>
        <mesh filename="package://pipebot_config/meshes/BR_hip_1.stl" scale="0.001 0.001 0.001"/>
      </geometry>
    </collision> -->
  </link>
  <link name="BL_hip_2">
    <inertial>
      <origin rpy="0 0 0" xyz="-0.05534530530946975 0.008821436558665116 -3.3029134982598407e-15"/>
      <mass value="0.5405625696384098"/>
      <inertia ixx="0.000528" ixy="-2e-06" ixz="0.0" iyy="0.000646" iyz="0.0" izz="0.000551"/>
    </inertial>
    <visual>
      <origin rpy="0 0 0" xyz="0.0903 -0.109725 -0.0675"/>
      <geometry>
        <mesh filename="package://pipebot_config/meshes/BL_hip_2.stl" scale="0.001 0.001 0.001"/>
      </geometry>
      <material name="silver"/>
    </visual>
   <!--  <collision>
      <origin rpy="0 0 0" xyz="0.0903 -0.109725 -0.0675"/>
      <geometry>
        <mesh filename="package://pipebot_config/meshes/BL_hip_2.stl" scale="0.001 0.001 0.001"/>
      </geometry>
    </collision> -->
  </link>
  <link name="FR_thigh_2">
    <inertial>
      <origin rpy="0 0 0" xyz="-1.752569043500518e-07 0.008553923180792372 -0.1460839641861526"/>
      <mass value="0.6712775800969663"/>
      <inertia ixx="0.004329" ixy="-0.0" ixz="-0.0" iyy="0.004392" iyz="0.000581" izz="0.000652"/>
    </inertial>
    <visual>
      <origin rpy="0 0 0" xyz="-0.1447 0.160275 -0.0675"/>
      <geometry>
        <mesh filename="package://pipebot_config/meshes/FR_thigh_2.stl" scale="0.001 0.001 0.001"/>
      </geometry>
      <material name="silver"/>
    </visual>
    <collision>
      <origin rpy="0 0 0" xyz="0.0 0.01 -0.085"/>
      <geometry>
        <!-- <mesh filename="package://pipebot_config/meshes/FR_thigh_2.stl" scale="0.001 0.001 0.001"/> -->
        <cylinder length="0.22" radius="0.035" />
      </geometry>
    </collision>
  </link>
  <link name="FL_thigh_1">
    <inertial>
      <origin rpy="0 0 0" xyz="-1.7525690446107411e-07 -0.008553199594087929 -0.1460839641861526"/>
      <mass value="0.6712775800969663"/>
      <inertia ixx="0.004329" ixy="-0.0" ixz="0.0" iyy="0.004392" iyz="-0.000581" izz="0.000652"/>
    </inertial>
    <visual>
      <origin rpy="0 0 0" xyz="-0.1447 -0.159725 -0.0675"/>
      <geometry>
        <mesh filename="package://pipebot_config/meshes/FL_thigh_1.stl" scale="0.001 0.001 0.001"/>
      </geometry>
      <material name="silver"/>
    </visual>
    <collision>
      <origin rpy="0 0 0" xyz="0.0 -0.01 -0.085"/>
      <geometry>
        <!-- <mesh filename="package://pipebot_config/meshes/FL_thigh_1.stl" scale="0.001 0.001 0.001"/> -->
        <cylinder length="0.22" radius="0.035" />
      </geometry>
    </collision>
  </link>
  <link name="BR_thigh_1">
    <inertial>
      <origin rpy="0 0 0" xyz="-1.7525690446107411e-07 0.008553923180792067 -0.14608396418615266"/>
      <mass value="0.6712775800969663"/>
      <inertia ixx="0.004329" ixy="0.0" ixz="0.0" iyy="0.004392" iyz="0.000581" izz="0.000652"/>
    </inertial>
    <visual>
      <origin rpy="0 0 0" xyz="0.1453 0.160275 -0.0675"/>
      <geometry>
        <mesh filename="package://pipebot_config/meshes/BR_thigh_1.stl" scale="0.001 0.001 0.001"/>
      </geometry>
      <material name="silver"/>
    </visual>
    <collision>
      <origin rpy="0 0 0" xyz="0.0 0.01 -0.085"/>
      <geometry>
        <!-- <mesh filename="package://pipebot_config/meshes/BR_thigh_1.stl" scale="0.001 0.001 0.001"/> -->
        <cylinder length="0.22" radius="0.035" />
      </geometry>
    </collision>
  </link>
  <link name="BL_thigh_1">
    <inertial>
      <origin rpy="0 0 0" xyz="-1.7525690432229624e-07 -0.008553199594087763 -0.14608396418615266"/>
      <mass value="0.6712775800969663"/>
      <inertia ixx="0.004329" ixy="0.0" ixz="-0.0" iyy="0.004392" iyz="-0.000581" izz="0.000652"/>
    </inertial>
    <visual>
      <origin rpy="0 0 0" xyz="0.1453 -0.159725 -0.0675"/>
      <geometry>
        <mesh filename="package://pipebot_config/meshes/BL_thigh_1.stl" scale="0.001 0.001 0.001"/>
      </geometry>
      <material name="silver"/>
    </visual>
    <collision>
      <origin rpy="0 0 0" xyz="0.0 -0.01 -0.085"/>
      <geometry>
        <!-- <mesh filename="package://pipebot_config/meshes/BL_thigh_1.stl" scale="0.001 0.001 0.001"/> -->
        <cylinder length="0.22" radius="0.035" />
      </geometry>
    </collision>
  </link>
  <link name="FR_calf_2">
    <inertial>
      <origin rpy="0 0 0" xyz="-6.545205563368572e-07 -0.026638451213781028 -0.06322775699684074"/>
      <mass value="0.44827046160119605"/>
      <inertia ixx="0.002095" ixy="0.0" ixz="0.0" iyy="0.002115" iyz="-7.1e-05" izz="0.000179"/>
    </inertial>
    <visual>
      <origin rpy="0 0 0" xyz="-0.1447 0.180275 0.1325"/>
      <geometry>
        <mesh filename="package://pipebot_config/meshes/FR_calf_2.stl" scale="0.001 0.001 0.001"/>
      </geometry>
      <material name="silver"/>
    </visual>
    <collision>
      <origin rpy="0 0 0" xyz="0.0 -0.03 -0.1"/>
      <geometry>
        <!-- <mesh filename="package://pipebot_config/meshes/FR_calf_2.stl" scale="0.001 0.001 0.001"/> -->
        <cylinder length="0.26" radius="0.02" />
      </geometry>
    </collision>
  </link>
  <link name="FL_calf_1">
    <inertial>
      <origin rpy="0 0 0" xyz="3.0400674758124246e-07 0.02663917480048489 -0.06322775699684105"/>
      <mass value="0.44827046160119605"/>
      <inertia ixx="0.002095" ixy="0.0" ixz="-0.0" iyy="0.002115" iyz="7.1e-05" izz="0.000179"/>
    </inertial>
    <visual>
      <origin rpy="0 0 0" xyz="-0.1447 -0.179725 0.1325"/>
      <geometry>
        <mesh filename="package://pipebot_config/meshes/FL_calf_1.stl" scale="0.001 0.001 0.001"/>
      </geometry>
      <material name="silver"/>
    </visual>
    <collision>
      <origin rpy="0 0 0" xyz="0.0 0.03 -0.1"/>
      <geometry>
        <!-- <mesh filename="package://pipebot_config/meshes/FL_calf_1.stl" scale="0.001 0.001 0.001"/> -->
        <cylinder length="0.26" radius="0.02" />
      </geometry>
    </collision>
  </link>
  <link name="BR_calf_1">
    <inertial>
      <origin rpy="0 0 0" xyz="-6.545205564478795e-07 -0.026638451213780612 -0.06322775699684094"/>
      <mass value="0.44827046160119605"/>
      <inertia ixx="0.002095" ixy="0.0" ixz="0.0" iyy="0.002115" iyz="-7.1e-05" izz="0.000179"/>
    </inertial>
    <visual>
      <origin rpy="0 0 0" xyz="0.1453 0.180275 0.1325"/>
      <geometry>
        <mesh filename="package://pipebot_config/meshes/BR_calf_1.stl" scale="0.001 0.001 0.001"/>
      </geometry>
      <material name="silver"/>
    </visual>
    <collision>
      <origin rpy="0 0 0" xyz="0.0 -0.03 -0.1"/>
      <geometry>
        <!-- <mesh filename="package://pipebot_config/meshes/BR_calf_1.stl" scale="0.001 0.001 0.001"/> -->
        <cylinder length="0.26" radius="0.02" />
      </geometry>
    </collision>
  </link>
  <link name="BL_calf_1">
    <inertial>
      <origin rpy="0 0 0" xyz="3.0400674780328707e-07 0.026639174800485 -0.06322775699683994"/>
      <mass value="0.44827046160119605"/>
      <inertia ixx="0.002095" ixy="0.0" ixz="-0.0" iyy="0.002115" iyz="7.1e-05" izz="0.000179"/>
    </inertial>
    <visual>
      <origin rpy="0 0 0" xyz="0.1453 -0.179725 0.1325"/>
      <geometry>
        <mesh filename="package://pipebot_config/meshes/BL_calf_1.stl" scale="0.001 0.001 0.001"/>
      </geometry>
      <material name="silver"/>
    </visual>
    <collision>
      <origin rpy="0 0 0" xyz="0.0 0.03 -0.1"/>
      <geometry>
        <!-- <mesh filename="package://pipebot_config/meshes/BL_calf_1.stl" scale="0.001 0.001 0.001"/> -->
        <cylinder length="0.26" radius="0.02" />
      </geometry>
    </collision>
  </link>

  <link name="ARM_1_1">
    <inertial>
      <origin rpy="0 0 0" xyz="-1.7525690418351836e-07 -0.005830729905288033 0.057375249759442165"/>
      <mass value="0.7137414944358373"/>
      <inertia ixx="0.000943" ixy="-0.0" ixz="-0.0" iyy="0.000925" iyz="1.1e-05" izz="0.000857"/>
    </inertial>
    <visual>
      <origin rpy="0 0 0" xyz="-0.1397 0.000275 -0.1915"/>
      <geometry>
        <mesh filename="package://pipebot_config/meshes/ARM_1_1.stl" scale="0.001 0.001 0.001"/>
      </geometry>
      <material name="silver"/>
    </visual>
    <collision>
      <origin rpy="0 0 0" xyz="0.0 0.0 0.06"/>
      <geometry>
        <!-- <mesh filename="package://pipebot_config/meshes/ARM_1_1.stl" scale="0.001 0.001 0.001"/> -->
        <sphere radius="0.05"/>
      </geometry>
    </collision>
  </link>
  <link name="ARM_2_1">
    <inertial>
      <origin rpy="0 0 0" xyz="-1.7525690415576278e-07 -0.02012141912775895 0.10000000000000003"/>
      <mass value="0.773912520513888"/>
      <inertia ixx="0.004467" ixy="-0.0" ixz="0.0" iyy="0.004728" iyz="0.0" izz="0.000448"/>
    </inertial>
    <visual>
      <origin rpy="0 0 0" xyz="-0.1397 0.056275 -0.2515"/>
      <geometry>
        <mesh filename="package://pipebot_config/meshes/ARM_2_1.stl" scale="0.001 0.001 0.001"/>
      </geometry>
      <material name="silver"/>
    </visual>
    <collision>
      <origin rpy="0 0 0" xyz="0.0 -0.02 0.1"/>
      <geometry>
        <!-- <mesh filename="package://pipebot_config/meshes/ARM_2_1.stl" scale="0.001 0.001 0.001"/> -->
        <cylinder length="0.26" radius="0.025" />
      </geometry>
    </collision>
  </link>
  <link name="ARM_3_1">
    <inertial>
      <origin rpy="0 0 0" xyz="-1.6744995820494601e-07 0.052205017987439005 0.03937119797670785"/>
      <mass value="0.8606075760650315"/>
      <inertia ixx="0.002133" ixy="0.0" ixz="-0.0" iyy="0.002006" iyz="-0.000203" izz="0.00081"/>
    </inertial>
    <visual>
      <origin rpy="0 0 0" xyz="-0.1397 0.056275 -0.4515"/>
      <geometry>
        <mesh filename="package://pipebot_config/meshes/ARM_3_1.stl" scale="0.001 0.001 0.001"/>
      </geometry>
      <material name="silver"/>
    </visual>
    <collision>
      <origin rpy="0 0 0" xyz="0.0 0.055 0.05"/>
      <geometry>
        <!-- <mesh filename="package://pipebot_config/meshes/ARM_3_1.stl" scale="0.001 0.001 0.001"/> -->
        <cylinder length="0.16" radius="0.035" />
      </geometry>
    </collision>
  </link>
  <link name="ARM_4_1">
    <inertial>
      <origin rpy="0 0 0" xyz="-3.009150454369447e-07 6.579991790117094e-07 0.04871488915431432"/>
      <mass value="0.16016196275303185"/>
      <inertia ixx="0.000446" ixy="0.0" ixz="-0.0" iyy="0.000233" iyz="0.0" izz="0.000344"/>
    </inertial>
    <visual>
      <origin rpy="0 0 0" xyz="-0.1397 -0.001725 -0.5765"/>
      <geometry>
        <mesh filename="package://pipebot_config/meshes/ARM_4_1.stl" scale="0.001 0.001 0.001"/>
      </geometry>
      <material name="silver"/>
    </visual>
    <!-- <collision>
      <origin rpy="0 0 0" xyz="-0.1397 -0.001725 -0.5765"/>
      <geometry>
        <mesh filename="package://pipebot_config/meshes/ARM_4_1.stl" scale="0.001 0.001 0.001"/>
      </geometry>
    </collision> -->
  </link>
  <link name="ARM_5_1">
    <inertial>
      <origin rpy="0 0 0" xyz="-1.6924779255855782e-07 0.045000352936759976 0.029600723352987135"/>
      <mass value="0.6278003275043091"/>
      <inertia ixx="0.001456" ixy="0.0" ixz="-0.0" iyy="0.001399" iyz="0.0" izz="0.000458"/>
    </inertial>
    <visual>
      <origin rpy="0 0 0" xyz="-0.1397 0.043275 -0.6515"/>
      <geometry>
        <mesh filename="package://pipebot_config/meshes/ARM_5_1.stl" scale="0.001 0.001 0.001"/>
      </geometry>
      <material name="silver"/>
    </visual>
    <collision>
      <origin rpy="0 0 0" xyz="0.0 0.045 0.045"/>
      <geometry>
        <!-- <mesh filename="package://pipebot_config/meshes/ARM_5_1.stl" scale="0.001 0.001 0.001"/> -->
        <cylinder length="0.16" radius="0.03" />
      </geometry>
    </collision>
  </link>
  <link name="ARM_6_1">
    <inertial>
      <origin rpy="0 0 0" xyz="-0.03224349227133551 4.51063936480838e-06 0.02024322382633237"/>
      <mass value="0.286612233804275"/>
      <inertia ixx="0.000168" ixy="0.0" ixz="4.1e-05" iyy="0.000239" iyz="-0.0" izz="0.000346"/>
    </inertial>
    <visual>
      <origin rpy="0 0 0" xyz="-0.1397 -0.001725 -0.7765"/>
      <geometry>
        <mesh filename="package://pipebot_config/meshes/ARM_6_1.stl" scale="0.001 0.001 0.001"/>
      </geometry>
      <material name="silver"/>
    </visual>
<!--     <collision>
      <origin rpy="0 0 0" xyz="-0.1397 -0.001725 -0.7765"/>
      <geometry>
        <mesh filename="package://pipebot_config/meshes/ARM_6_1.stl" scale="0.001 0.001 0.001"/>
      </geometry>
    </collision> -->
  </link>

  <link name="FL_foot_1">
    <inertial>
      <origin rpy="0 0 0" xyz="-1.7525690432229624e-07 3.6179335244357347e-07 -0.0018890805472966399"/>
      <mass value="0.05646802367385563"/>
      <inertia ixx="1.4e-05" ixy="0.0" ixz="0.0" iyy="1.4e-05" iyz="0.0" izz="1.6e-05"/>
    </inertial>
    <visual>
      <origin rpy="0 0 0" xyz="-0.1447 -0.209725 0.3825"/>
      <geometry>
        <mesh filename="package://pipebot_config/meshes/FL_foot_1.stl" scale="0.001 0.001 0.001"/>
      </geometry>
      <material name="silver"/>
    </visual>
    <collision>
      <origin rpy="0 0 0" xyz="0.0 0.0 0.0"/>
      <geometry>
        <!-- <mesh filename="package://pipebot_config/meshes/FL_foot_1.stl" scale="0.001 0.001 0.001"/> -->
        <sphere radius="0.03" />
      </geometry>
    </collision>
  </link>
  <link name="FR_foot_1">
    <inertial>
      <origin rpy="0 0 0" xyz="-1.7525690426678509e-07 3.617933521660177e-07 -0.0018890805472965844"/>
      <mass value="0.05646802367385563"/>
      <inertia ixx="1.4e-05" ixy="-0.0" ixz="0.0" iyy="1.4e-05" iyz="0.0" izz="1.6e-05"/>
    </inertial>
    <visual>
      <origin rpy="0 0 0" xyz="-0.1447 0.210275 0.3825"/>
      <geometry>
        <mesh filename="package://pipebot_config/meshes/FR_foot_1.stl" scale="0.001 0.001 0.001"/>
      </geometry>
      <material name="silver"/>
    </visual>
    <collision>
      <origin rpy="0 0 0" xyz="0.0 0.0 0.0"/>
      <geometry>
        <!-- <mesh filename="package://pipebot_config/meshes/FR_foot_1.stl" scale="0.001 0.001 0.001"/> -->
        <sphere radius="0.03" />
      </geometry>
    </collision>
  </link>
  <link name="BR_foot_4">
    <inertial>
      <origin rpy="0 0 0" xyz="-1.752569043500518e-07 3.6179335222152886e-07 -0.0018890805472984162"/>
      <mass value="0.05646802367385563"/>
      <inertia ixx="1.4e-05" ixy="-0.0" ixz="0.0" iyy="1.4e-05" iyz="-0.0" izz="1.6e-05"/>
    </inertial>
    <visual>
      <origin rpy="0 0 0" xyz="0.1453 0.210275 0.3825"/>
      <geometry>
        <mesh filename="package://pipebot_config/meshes/BR_foot_4.stl" scale="0.001 0.001 0.001"/>
      </geometry>
      <material name="silver"/>
    </visual>
    <collision>
      <origin rpy="0 0 0" xyz="0.0 0.0 0.0"/>
      <geometry>
        <!-- <mesh filename="package://pipebot_config/meshes/BR_foot_4.stl" scale="0.001 0.001 0.001"/> -->
        <sphere radius="0.03" />
      </geometry>
    </collision>
  </link>
  <link name="BL_foot_1">
    <inertial>
      <origin rpy="0 0 0" xyz="-1.7525690507169678e-07 3.617933526101069e-07 -0.0018890805472970285"/>
      <mass value="0.05646802367385563"/>
      <inertia ixx="1.4e-05" ixy="0.0" ixz="0.0" iyy="1.4e-05" iyz="0.0" izz="1.6e-05"/>
    </inertial>
    <visual>
      <origin rpy="0 0 0" xyz="0.1453 -0.209725 0.3825"/>
      <geometry>
        <mesh filename="package://pipebot_config/meshes/BL_foot_1.stl" scale="0.001 0.001 0.001"/>
      </geometry>
      <material name="silver"/>
    </visual>
    <collision>
      <origin rpy="0 0 0" xyz="0.0 0.0 0.0"/>
      <geometry>
        <!-- <mesh filename="package://pipebot_config/meshes/BL_foot_1.stl" scale="0.001 0.001 0.001"/> -->
        <sphere radius="0.03" />
      </geometry>
    </collision>
  </link>


  <link name="robotiq_arg2f_base_link">
    <inertial>
      <origin rpy="0 0 0" xyz="8.625E-08 -4.6583E-06 0.03145"/>
      <mass value="0.22652"/>
      <inertia ixx="0.00020005" ixy="-4.2442E-10" ixz="-2.9069E-10" iyy="0.00017832" iyz="-3.4402E-08" izz="0.00013478"/>
    </inertial>
    <visual>
      <origin rpy="0 0 0" xyz="0 0 0"/>
      <geometry>
        <mesh filename="package://pipebot_config/meshes/visual/robotiq_arg2f_base_link.stl"/>
      </geometry>
      <material name="">
        <color rgba="0.1 0.1 0.1 1"/>
      </material>
    </visual>
    <collision>
      <origin rpy="0 0 0" xyz="0 0 0.04"/>
      <geometry>
        <!-- <mesh filename="package://pipebot_config/meshes/collision/robotiq_arg2f_base_link.stl"/> -->
        <cylinder length="0.08" radius="0.04"/>
      </geometry>
    </collision>
  </link>
  <link name="left_outer_knuckle">
    <inertial>
      <origin rpy="0 0 0" xyz="-0.000200000000003065 0.0199435877845359 0.0292245259211331"/>
      <mass value="0.00853198276973456"/>
      <inertia ixx="2.89328108496468E-06" ixy="-1.57935047237397E-19" ixz="-1.93980378593255E-19" iyy="1.86719750325683E-06" iyz="-1.21858577871576E-06" izz="1.21905238907251E-06"/>
    </inertial>
    <visual>
      <origin rpy="0 0 0" xyz="0 0 0"/>
      <geometry>
        <mesh filename="package://pipebot_config/meshes/visual/robotiq_arg2f_140_outer_knuckle.stl"/>
      </geometry>
      <material name="">
        <color rgba="0.792156862745098 0.819607843137255 0.933333333333333 1"/>
      </material>
    </visual>
<!--     <collision>
      <origin rpy="0 0 0" xyz="0 0 0"/>
      <geometry>
        <mesh filename="package://pipebot_config/meshes/collision/robotiq_arg2f_140_outer_knuckle.stl"/>
      </geometry>
    </collision> -->
  </link>
  <link name="left_outer_finger">
    <inertial>
      <origin rpy="0 0 0" xyz="0.00030115855001899 0.0373907951953854 -0.0208027427000385"/>
      <mass value="0.022614240507152"/>
      <inertia ixx="1.52518312458174E-05" ixy="9.76583423954399E-10" ixz="-5.43838577022588E-10" iyy="6.17694243867776E-06" iyz="6.78636130740228E-06" izz="1.16494917907219E-05"/>
    </inertial>
    <visual>
      <origin rpy="0 0 0" xyz="0 0 0"/>
      <geometry>
        <mesh filename="package://pipebot_config/meshes/visual/robotiq_arg2f_140_outer_finger.stl"/>
      </geometry>
      <material name="">
        <color rgba="0.1 0.1 0.1 1"/>
      </material>
    </visual>
    <collision>
      <origin rpy="1.3 0 0" xyz="0 0.04 -0.018"/>
      <geometry>
        <!-- <mesh filename="package://pipebot_config/meshes/collision/robotiq_arg2f_140_outer_finger.stl"/> -->
        <box size="0.03 0.01 0.1"/>
      </geometry>
    </collision>
  </link>
  <link name="left_inner_finger">
    <inertial>
      <origin rpy="0 0 0" xyz="0.000299999999999317 0.0160078233491243 -0.0136945669206257"/>
      <mass value="0.0104003125914103"/>
      <inertia ixx="2.71909453810972E-06" ixy="1.35402465472579E-21" ixz="-7.1817349065269E-22" iyy="7.69100314106116E-07" iyz="6.74715432769696E-07" izz="2.30315190420171E-06"/>
    </inertial>
    <visual>
      <origin rpy="0 0 0" xyz="0 0 0"/>
      <geometry>
        <mesh filename="package://pipebot_config/meshes/visual/robotiq_arg2f_140_inner_finger.stl"/>
      </geometry>
      <material name="">
        <color rgba="0.1 0.1 0.1 1"/>
      </material>
    </visual>
    <collision>
      <origin rpy="1.5708 0 0" xyz="0 0.02 -0.015"/>
      <geometry>
        <!-- <mesh filename="package://pipebot_config/meshes/collision/robotiq_arg2f_140_inner_finger.stl"/> -->
        <box size="0.015 0.015 0.05"/>
      </geometry>
    </collision>
  </link>
  <link name="left_inner_finger_pad">
    <visual>
      <origin rpy="0 0 0" xyz="0 0 0"/>
      <geometry>
        <box size="0.027 0.065 0.0075"/>
      </geometry>
      <material name="">
        <color rgba="0.792156862745098 0.819607843137255 0.933333333333333 1"/>
      </material>
    </visual>
    <collision>
      <origin rpy="0 0 0" xyz="0 0 0"/>
      <geometry>
        <box size="0.03 0.07 0.0075"/>
      </geometry>
    </collision>
  </link>
  <link name="left_inner_knuckle">
    <inertial>
      <origin rpy="0 0 0" xyz="0.000123011831763771 0.0507850843201817 0.00103968640075166"/>
      <mass value="0.0271177346495152"/>
      <inertia ixx="2.61910379223783E-05" ixy="-2.43616858946494E-07" ixz="-6.37789906117123E-09" iyy="2.8270243746167E-06" iyz="-5.37200748039765E-07" izz="2.83695868220296E-05"/>
    </inertial>
    <visual>
      <origin rpy="0 0 0" xyz="0 0 0"/>
      <geometry>
        <mesh filename="package://pipebot_config/meshes/visual/robotiq_arg2f_140_inner_knuckle.stl"/>
      </geometry>
      <material name="">
        <color rgba="0.1 0.1 0.1 1"/>
      </material>
    </visual>
    <collision>
      <origin rpy="1.58 0 0" xyz="0 0.04 0.0"/>
      <geometry>
        <!-- <mesh filename="package://pipebot_config/meshes/collision/robotiq_arg2f_140_inner_knuckle.stl"/> -->
        <box size="0.03 0.015 0.11"/>
      </geometry>
    </collision>
  </link>
  <link name="right_outer_knuckle">
    <inertial>
      <origin rpy="0 0 0" xyz="-0.000200000000003065 0.0199435877845359 0.0292245259211331"/>
      <mass value="0.00853198276973456"/>
      <inertia ixx="2.89328108496468E-06" ixy="-1.57935047237397E-19" ixz="-1.93980378593255E-19" iyy="1.86719750325683E-06" iyz="-1.21858577871576E-06" izz="1.21905238907251E-06"/>
    </inertial>
    <visual>
      <origin rpy="0 0 0" xyz="0 0 0"/>
      <geometry>
        <mesh filename="package://pipebot_config/meshes/visual/robotiq_arg2f_140_outer_knuckle.stl"/>
      </geometry>
      <material name="">
        <color rgba="0.792156862745098 0.819607843137255 0.933333333333333 1"/>
      </material>
    </visual>
<!--     <collision>
      <origin rpy="0 0 0" xyz="0 0 0"/>
      <geometry>
        <mesh filename="package://pipebot_config/meshes/collision/robotiq_arg2f_140_outer_knuckle.stl"/>
      </geometry>
    </collision> -->
  </link>
  <link name="right_outer_finger">
    <inertial>
      <origin rpy="0 0 0" xyz="0.00030115855001899 0.0373907951953854 -0.0208027427000385"/>
      <mass value="0.022614240507152"/>
      <inertia ixx="1.52518312458174E-05" ixy="9.76583423954399E-10" ixz="-5.43838577022588E-10" iyy="6.17694243867776E-06" iyz="6.78636130740228E-06" izz="1.16494917907219E-05"/>
    </inertial>
    <visual>
      <origin rpy="0 0 0" xyz="0 0 0"/>
      <geometry>
        <mesh filename="package://pipebot_config/meshes/visual/robotiq_arg2f_140_outer_finger.stl"/>
      </geometry>
      <material name="">
        <color rgba="0.1 0.1 0.1 1"/>
      </material>
    </visual>
    <collision>
      <origin rpy="1.3 0 0" xyz="0 0.04 -0.018"/>
      <geometry>
        <!-- <mesh filename="package://pipebot_config/meshes/collision/robotiq_arg2f_140_outer_finger.stl"/> -->
        <box size="0.03 0.01 0.1"/>
      </geometry>
    </collision>
  </link>
  <link name="right_inner_finger">
    <inertial>
      <origin rpy="0 0 0" xyz="0.000299999999999317 0.0160078233491243 -0.0136945669206257"/>
      <mass value="0.0104003125914103"/>
      <inertia ixx="2.71909453810972E-06" ixy="1.35402465472579E-21" ixz="-7.1817349065269E-22" iyy="7.69100314106116E-07" iyz="6.74715432769696E-07" izz="2.30315190420171E-06"/>
    </inertial>
    <visual>
      <origin rpy="0 0 0" xyz="0 0 0"/>
      <geometry>
        <mesh filename="package://pipebot_config/meshes/visual/robotiq_arg2f_140_inner_finger.stl"/>
      </geometry>
      <material name="">
        <color rgba="0.1 0.1 0.1 1"/>
      </material>
    </visual>
    <collision>
      <origin rpy="1.5708 0 0" xyz="0 0.02 -0.015"/>
      <geometry>
        <!-- <mesh filename="package://pipebot_config/meshes/collision/robotiq_arg2f_140_inner_finger.stl"/> -->
        <box size="0.015 0.015 0.05"/>
      </geometry>
    </collision>
  </link>
  <link name="right_inner_finger_pad">
    <visual>
      <origin rpy="0 0 0" xyz="0 0 0"/>
      <geometry>
        <box size="0.027 0.065 0.0075"/>
      </geometry>
      <material name="">
        <color rgba="0.792156862745098 0.819607843137255 0.933333333333333 1"/>
      </material>
    </visual>
    <collision>
      <origin rpy="0 0 0" xyz="0 0 0"/>
      <geometry>
        <box size="0.03 0.07 0.0075"/>
      </geometry>
    </collision>
  </link>
  <link name="right_inner_knuckle">
    <inertial>
      <origin rpy="0 0 0" xyz="0.000123011831763771 0.0507850843201817 0.00103968640075166"/>
      <mass value="0.0271177346495152"/>
      <inertia ixx="2.61910379223783E-05" ixy="-2.43616858946494E-07" ixz="-6.37789906117123E-09" iyy="2.8270243746167E-06" iyz="-5.37200748039765E-07" izz="2.83695868220296E-05"/>
    </inertial>
    <visual>
      <origin rpy="0 0 0" xyz="0 0 0"/>
      <geometry>
        <mesh filename="package://pipebot_config/meshes/visual/robotiq_arg2f_140_inner_knuckle.stl"/>
      </geometry>
      <material name="">
        <color rgba="0.1 0.1 0.1 1"/>
      </material>
    </visual>
    <collision>
      <origin rpy="-1.58 0 0" xyz="0 0.04 0.0"/>
      <geometry>
        <!-- <mesh filename="package://pipebot_config/meshes/collision/robotiq_arg2f_140_inner_knuckle.stl"/> -->
        <box size="0.03 0.015 0.11"/>
      </geometry>
    </collision>
  </link>


  <joint name="FR_hip_joint" type="continuous">
    <origin rpy="0 0 0" xyz="0.0897 -0.110275 0.0675"/>
    <parent link="base_link"/>
    <child link="FR_hip_1"/>
    <axis xyz="1.0 -0.0 0.0"/>
    <limit command_effort="40" current="10" effort="80" gear_velocity="10" lower="-3.0" upper="3.0" velocity="15.0" />
  </joint>
  <joint name="FL_hip_joint" type="continuous">
    <origin rpy="0 0 0" xyz="0.0897 0.109725 0.0675"/>
    <parent link="base_link"/>
    <child link="FL_hip_1"/>
    <axis xyz="1.0 -0.0 0.0"/>
    <limit command_effort="40" current="10" effort="80" gear_velocity="10" lower="-3.0" upper="3.0" velocity="15.0" />
  </joint>
  <joint name="BR_hip_joint" type="continuous">
    <origin rpy="0 0 0" xyz="-0.0903 -0.110275 0.0675"/>
    <parent link="base_link"/>
    <child link="BR_hip_1"/>
    <axis xyz="1.0 0.0 -0.0"/>
    <limit command_effort="40" current="10" effort="80" gear_velocity="10" lower="-3.0" upper="3.0" velocity="15.0" />
  </joint>
  <joint name="BL_hip_joint" type="continuous">
    <origin rpy="0 0 0" xyz="-0.0903 0.109725 0.0675"/>
    <parent link="base_link"/>
    <child link="BL_hip_2"/>
    <axis xyz="1.0 0.0 -0.0"/>
    <limit command_effort="40" current="10" effort="80" gear_velocity="10" lower="-3.0" upper="3.0" velocity="15.0" />
  </joint>
  <joint name="FR_thigh_joint" type="continuous">
    <origin rpy="0 0 0" xyz="0.055 -0.05 0.0"/>
    <parent link="FR_hip_1"/>
    <child link="FR_thigh_2"/>
    <axis xyz="0.0 1.0 -0.0"/>
    <limit command_effort="40" current="10" effort="80" gear_velocity="10" lower="-3.0" upper="3.0" velocity="15.0" />
  </joint>
  <joint name="FL_thigh_joint" type="continuous">
    <origin rpy="0 0 0" xyz="0.055 0.05 0.0"/>
    <parent link="FL_hip_1"/>
    <child link="FL_thigh_1"/>
    <axis xyz="-0.0 1.0 -0.0"/>
    <limit command_effort="40" current="10" effort="80" gear_velocity="10" lower="-3.0" upper="3.0" velocity="15.0" />
  </joint>
  <joint name="BR_thigh_joint" type="continuous">
    <origin rpy="0 0 0" xyz="-0.055 -0.05 0.0"/>
    <parent link="BR_hip_1"/>
    <child link="BR_thigh_1"/>
    <axis xyz="0.0 1.0 0.0"/>
    <limit command_effort="40" current="10" effort="80" gear_velocity="10" lower="-3.0" upper="3.0" velocity="15.0" />
  </joint>
  <joint name="BL_thigh_joint" type="continuous">
    <origin rpy="0 0 0" xyz="-0.055 0.05 0.0"/>
    <parent link="BL_hip_2"/>
    <child link="BL_thigh_1"/>
    <axis xyz="-0.0 1.0 0.0"/>
    <limit command_effort="40" current="10" effort="80" gear_velocity="10" lower="-3.0" upper="3.0" velocity="15.0" />
  </joint>
  <joint name="FR_calf_joint" type="continuous">
    <origin rpy="0 0 0" xyz="0.0 -0.02 -0.2"/>
    <parent link="FR_thigh_2"/>
    <child link="FR_calf_2"/>
    <axis xyz="0.0 1.0 -0.0"/>
    <limit command_effort="40" current="10" effort="80" gear_velocity="10" lower="-3.0" upper="3.0" velocity="15.0" />
  </joint>
  <joint name="FL_calf_joint" type="continuous">
    <origin rpy="0 0 0" xyz="0.0 0.02 -0.2"/>
    <parent link="FL_thigh_1"/>
    <child link="FL_calf_1"/>
    <axis xyz="-0.0 1.0 -0.0"/>
    <limit command_effort="40" current="10" effort="80" gear_velocity="10" lower="-3.0" upper="3.0" velocity="15.0" />
  </joint>
  <joint name="BR_calf_joint" type="continuous">
    <origin rpy="0 0 0" xyz="0.0 -0.02 -0.2"/>
    <parent link="BR_thigh_1"/>
    <child link="BR_calf_1"/>
    <axis xyz="0.0 1.0 0.0"/>
    <limit command_effort="40" current="10" effort="80" gear_velocity="10" lower="-3.0" upper="3.0" velocity="15.0" />
  </joint>
  <joint name="BL_calf_joint" type="continuous">
    <origin rpy="0 0 0" xyz="0.0 0.02 -0.2"/>
    <parent link="BL_thigh_1"/>
    <child link="BL_calf_1"/>
    <axis xyz="-0.0 1.0 0.0"/>
    <limit command_effort="40" current="10" effort="80" gear_velocity="10" lower="-3.0" upper="3.0" velocity="15.0" />
  </joint>
    <joint name="FL_foot_fixed" type="fixed">
    <origin rpy="0 0 0" xyz="0.0 0.03 -0.25"/>
    <parent link="FL_calf_1"/>
    <child link="FL_foot_1"/>
  </joint>
  <joint name="FR_foot_fixed" type="fixed">
    <origin rpy="0 0 0" xyz="0.0 -0.03 -0.25"/>
    <parent link="FR_calf_2"/>
    <child link="FR_foot_1"/>
  </joint>
  <joint name="BR_foot_fixed" type="fixed">
    <origin rpy="0 0 0" xyz="0.0 -0.03 -0.25"/>
    <parent link="BR_calf_1"/>
    <child link="BR_foot_4"/>
  </joint>
  <joint name="BL_foot_fixed" type="fixed">
    <origin rpy="0 0 0" xyz="0.0 0.03 -0.25"/>
    <parent link="BL_calf_1"/>
    <child link="BL_foot_1"/>
  </joint>
  <joint name="arm_1_joint" type="continuous">
    <origin rpy="0 0 0" xyz="0.1397 -0.000275 0.1915"/>
    <parent link="base_link"/>
    <child link="ARM_1_1"/>
    <axis xyz="0.0 0.0 1.0"/>
    <limit command_effort="40" current="10" effort="80" gear_velocity="10" lower="-3.0" upper="3.0" velocity="15.0" />
  </joint>
  <joint name="arm_2_joint" type="continuous">
    <origin rpy="0 0 0" xyz="0.0 -0.056 0.06"/>
    <parent link="ARM_1_1"/>
    <child link="ARM_2_1"/>
    <axis xyz="-0.0 1.0 -0.0"/>
    <limit command_effort="40" current="10" effort="80" gear_velocity="10" lower="-3.0" upper="3.0" velocity="15.0" />
  </joint>
  <joint name="arm_3_joint" type="continuous">
    <origin rpy="0 0 0" xyz="0.0 0.0 0.2"/>
    <parent link="ARM_2_1"/>
    <child link="ARM_3_1"/>
    <axis xyz="0.0 -1.0 0.0"/>
    <limit command_effort="40" current="10" effort="80" gear_velocity="10" lower="-3.0" upper="3.0" velocity="15.0" />
  </joint>
  <joint name="arm_4_joint" type="continuous">
    <origin rpy="0 0 0" xyz="0.0 0.058 0.125"/>
    <parent link="ARM_3_1"/>
    <child link="ARM_4_1"/>
    <axis xyz="-0.0 0.0 1.0"/>
    <limit command_effort="40" current="10" effort="80" gear_velocity="10" lower="-3.0" upper="3.0" velocity="15.0" />
  </joint>
  <joint name="arm_5_joint" type="continuous">
    <origin rpy="0 0 0" xyz="0.0 -0.045 0.075"/>
    <parent link="ARM_4_1"/>
    <child link="ARM_5_1"/>
    <axis xyz="0.0 -1.0 0.0"/>
    <limit command_effort="40" current="10" effort="80" gear_velocity="10" lower="-3.0" upper="3.0" velocity="15.0" />
  </joint>
  <joint name="arm_6_joint" type="continuous">
    <origin rpy="0 0 0" xyz="0.0 0.045 0.125"/>
    <parent link="ARM_5_1"/>
    <child link="ARM_6_1"/>
    <axis xyz="-0.0 0.0 1.0"/>
    <limit command_effort="40" current="10" effort="80" gear_velocity="10" lower="-3.0" upper="3.0" velocity="15.0" />
  </joint>

  <joint name="arm_6_finger_joint" type="fixed">
    <origin rpy="0 0 0" xyz="0.0 0.0 0.02"/>
    <parent link="ARM_6_1"/>
    <child link="robotiq_arg2f_base_link"/>
  </joint>
  <joint name="finger_joint" type="revolute">
    <origin rpy="2.29579632679 0 0" xyz="0 -0.030601 0.054905"/>
    <parent link="robotiq_arg2f_base_link"/>
    <child link="left_outer_knuckle"/>
    <axis xyz="-1 0 0"/>
    <limit effort="1000" lower="0" upper="0.7" velocity="2.0"/>
  </joint>
  <joint name="left_outer_finger_joint" type="fixed">
    <origin rpy="0 0 0" xyz="0 0.01821998610742 0.0260018192872234"/>
    <parent link="left_outer_knuckle"/>
    <child link="left_outer_finger"/>
    <axis xyz="1 0 0"/>
  </joint>
  <joint name="left_inner_knuckle_joint" type="revolute">
    <origin rpy="2.29579632679 0 0.0" xyz="0 -0.0127 0.06142"/>
    <parent link="robotiq_arg2f_base_link"/>
    <child link="left_inner_knuckle"/>
    <axis xyz="-1 0 0"/>
    <limit effort="1000" lower="0" upper="0.8757" velocity="2.0"/>
  </joint>
  <joint name="left_inner_finger_joint" type="revolute">
    <origin rpy="-0.725 0 0" xyz="0 0.0817554015893473 -0.0282203446692936"/>
    <parent link="left_outer_finger"/>
    <child link="left_inner_finger"/>
    <axis xyz="-1 0 0"/>
    <limit effort="1000" lower="-0.8757" upper="0.0" velocity="2.0"/>
  </joint>
  <joint name="left_inner_finger_pad_joint" type="fixed">
    <origin rpy="0 0 0" xyz="0 0.0457554015893473 -0.0272203446692936"/>
    <parent link="left_inner_finger"/>
    <child link="left_inner_finger_pad"/>
    <axis xyz="0 0 1"/>
  </joint>
  <joint name="right_outer_knuckle_joint" type="revolute">
    <origin rpy="2.29579632679 0 3.14159265359" xyz="0 0.030601 0.054905"/>
    <parent link="robotiq_arg2f_base_link"/>
    <child link="right_outer_knuckle"/>
    <axis xyz="-1 0 0"/>
    <limit effort="1000" lower="0" upper="0.725" velocity="2.0"/>
  </joint>
  <joint name="right_outer_finger_joint" type="fixed">
    <origin rpy="0 0 0" xyz="0 0.01821998610742 0.0260018192872234"/>
    <parent link="right_outer_knuckle"/>
    <child link="right_outer_finger"/>
    <axis xyz="1 0 0"/>
  </joint>
  <joint name="right_inner_knuckle_joint" type="revolute">
    <origin rpy="2.29579632679 0 -3.14159265359" xyz="0 0.0127 0.06142"/>
    <parent link="robotiq_arg2f_base_link"/>
    <child link="right_inner_knuckle"/>
    <axis xyz="-1 0 0"/>
    <limit effort="1000" lower="0" upper="0.8757" velocity="2.0"/>
  </joint>
  <joint name="right_inner_finger_joint" type="revolute">
    <origin rpy="-0.725 0 0" xyz="0 0.0817554015893473 -0.0282203446692936"/>
    <parent link="right_outer_finger"/>
    <child link="right_inner_finger"/>
    <axis xyz="-1 0 0"/>
    <limit effort="1000" lower="-0.8757" upper="0.0" velocity="2.0"/>
  </joint>
  <joint name="right_inner_finger_pad_joint" type="fixed">
    <origin rpy="0 0 0" xyz="0 0.0457554015893473 -0.0272203446692936"/>
    <parent link="right_inner_finger"/>
    <child link="right_inner_finger_pad"/>
    <axis xyz="0 0 1"/>
  </joint>

  <!--  IMU link -->
   <link name="imu_link">
    <inertial>
      <mass value="0.01"/>
      <inertia ixx="1.0e-5" ixy="0.0" ixz="0.0" iyy="1.0e-5" iyz="0.0" izz="1.0e-5"/>
    </inertial>
   </link>
   <joint name="imu_base" type="fixed">
      <parent link="base_link" />
      <child link="imu_link" />
      <origin rpy="0 0 0" xyz="0 0 0" />
   </joint>

  <gazebo reference="imu_link">
    <gravity>true</gravity>
    <sensor name="imu_sensor" type="imu">
      <always_on>true</always_on>
      <update_rate>100</update_rate>
      <visualize>true</visualize>
      <topic>__default_topic__</topic>
      <plugin filename="libgazebo_ros_imu_sensor.so" name="imu_plugin">
        <topicName>imu</topicName>
        <bodyName>imu_link</bodyName>
        <updateRateHZ>100.0</updateRateHZ>
        <gaussianNoise>0.0</gaussianNoise>
        <xyzOffset>0 0 0</xyzOffset>
        <rpyOffset>0 0 0</rpyOffset>
        <frameName>imu_link</frameName>
        <initialOrientationAsReference>false</initialOrientationAsReference>
      </plugin>
      <pose>0 0 0 0 0 0</pose>
    </sensor>
  </gazebo>

  <!--  Camera link -->
  <link name="d435_link">
    <inertial>
      <mass value="0.01"/>
      <inertia ixx="1.0e-5" ixy="0.0" ixz="0.0" iyy="1.0e-5" iyz="0.0" izz="1.0e-5"/>
    </inertial>
  </link>
  <joint name="cam_fixed_d435" type="fixed">
    <axis xyz="1 0 0"/>
    <origin rpy="0 -1.5708 0" xyz="-0.04 0 0.05"/>
    <parent link="ARM_6_1"/>
    <child link="d435_link"/>
  </joint>
  <gazebo reference="d435_link">
    <sensor type="multicamera" name="stereo_camera">
      <camera name="left">
        <pose>0 0 0 0 0 0</pose>
        <horizontal_fov>1.518</horizontal_fov>
        <image>
          <width>1280</width>
          <height>720</height>
          <format>R8G8B8</format>
        </image>
        <clip>
          <near>0.02</near>
          <far>30000</far>
        </clip>
        <noise>
          <type>gaussian</type>
          <mean>0.0</mean>
          <stddev>0.001</stddev>
        </noise>
      </camera>
      <camera name="right">
        <pose>0 -0.05 0 0 0 0</pose>
        <horizontal_fov>1.518</horizontal_fov>
        <image>
          <width>1280</width>
          <height>720</height>
          <format>R8G8B8</format>
        </image>
        <clip>
          <near>0.02</near>
          <far>30000</far>
        </clip>
        <noise>
          <type>gaussian</type>
          <mean>0.0</mean>
          <stddev>0.001</stddev>
        </noise>
      </camera>
      <always_on>1</always_on>
      <visualize>1</visualize>
      <update_rate>10.0</update_rate>
      <plugin name="stereo_camera_controller" filename="libgazebo_ros_multicamera.so">
        <robotNamespace>/d435</robotNamespace>
        <baseline>0.05</baseline>
        <alwaysOn>true</alwaysOn>
        <updateRate>10.0</updateRate>
        <cameraName>stereo_ir</cameraName>
        <imageTopicName>image_raw</imageTopicName>
        <cameraInfoTopicName>camera_info</cameraInfoTopicName>
        <frameName>d435_camera_link</frameName>
        <hackBaseline>0.05</hackBaseline>
      </plugin>
    </sensor>
    <sensor name="dcamera" type="depth">
      <camera name="ddepth">
        <horizontal_fov>1.518</horizontal_fov>
        <image>
          <width>1280</width>
          <height>720</height>
          <format>R8G8B8</format>
        </image>
        <clip>
          <near>0.02</near>
          <far>30000</far>
        </clip>
        <noise>
          <type>gaussian</type>
          <mean>0.0</mean>
          <stddev>0.001</stddev>
        </noise>
      </camera>
      <always_on>1</always_on>
      <visualize>1</visualize>
      <update_rate>10</update_rate>
      <plugin name="dcamera_plugin" filename="libgazebo_ros_openni_kinect.so">
        <robotNamespace>/d435</robotNamespace>
        <baseline>0.05</baseline>
        <alwaysOn>true</alwaysOn>
        <updateRate>10.0</updateRate>
        <cameraName>depth</cameraName>
        <imageTopicName>rgb_image_raw</imageTopicName>
        <cameraInfoTopicName>camera_info</cameraInfoTopicName>
        <depthImageTopicName>image_raw</depthImageTopicName>
        <depthImageCameraInfoTopicName>camera_info</depthImageCameraInfoTopicName>
        <pointCloudTopicName>pointcloud</pointCloudTopicName>
        <frameName>d435_camera_link</frameName>
        <pointCloudCutoff>0.3</pointCloudCutoff>
        <pointCloudCutoffMax>4.0</pointCloudCutoffMax>
        <hackBaseline>0.05</hackBaseline>
      </plugin>
    </sensor>
  </gazebo>

  <!--  Camera link -->
  <link name="l515_link">
    <inertial>
      <mass value="0.01"/>
      <inertia ixx="1.0e-5" ixy="0.0" ixz="0.0" iyy="1.0e-5" iyz="0.0" izz="1.0e-5"/>
    </inertial>
  </link>
  <joint name="cam_fixed_l515" type="fixed">
    <axis xyz="1 0 0"/>
    <origin rpy="0 0 0" xyz="0.28 0 0.08"/>
    <parent link="base_link"/>
    <child link="l515_link"/>
  </joint>
  <gazebo reference="l515_link">
    <sensor name="camera" type="depth">
      <camera name="depth">
        <horizontal_fov>1.217</horizontal_fov>
        <image>
          <width>1024</width>
          <height>768</height>
          <format>R8G8B8</format>
        </image>
        <clip>
          <near>0.02</near>
          <far>30000</far>
        </clip>
        <noise>
          <type>gaussian</type>
          <mean>0.0</mean>
          <stddev>0.001</stddev>
        </noise>
      </camera>
      <always_on>1</always_on>
      <visualize>1</visualize>
      <update_rate>10</update_rate>
      <plugin name="camera_plugin" filename="libgazebo_ros_openni_kinect.so">
        <robotNamespace>/l515</robotNamespace>
        <baseline>0.03</baseline>
        <alwaysOn>true</alwaysOn>
        <updateRate>10.0</updateRate>
        <cameraName>depth</cameraName>
        <imageTopicName>rgb_image_raw</imageTopicName>
        <cameraInfoTopicName>rgb_camera_info</cameraInfoTopicName>
        <depthImageTopicName>image_raw</depthImageTopicName>
        <depthImageCameraInfoTopicName>camera_info</depthImageCameraInfoTopicName>
        <pointCloudTopicName>pointcloud</pointCloudTopicName>
        <frameName>l515_camera_link</frameName>
        <pointCloudCutoff>0.25</pointCloudCutoff>
        <pointCloudCutoffMax>9.0</pointCloudCutoffMax>
        <hackBaseline>0.03</hackBaseline>
      </plugin>
    </sensor>
  </gazebo>

  <!--  Camera link -->
  <link name="l515_link_back">
    <inertial>
      <mass value="0.01"/>
      <inertia ixx="1.0e-5" ixy="0.0" ixz="0.0" iyy="1.0e-5" iyz="0.0" izz="1.0e-5"/>
    </inertial>
  </link>
  <joint name="cam_fixed_l515_back" type="fixed">
    <axis xyz="1 0 0"/>
    <origin rpy="0 0 3.141592" xyz="-0.28 0 0.08"/>
    <parent link="base_link"/>
    <child link="l515_link_back"/>
  </joint>
  <gazebo reference="l515_link_back">
    <sensor name="camera" type="depth">
      <camera name="depth">
        <horizontal_fov>1.217</horizontal_fov>
        <image>
          <width>1024</width>
          <height>768</height>
          <format>R8G8B8</format>
        </image>
        <clip>
          <near>0.02</near>
          <far>30000</far>
        </clip>
        <noise>
          <type>gaussian</type>
          <mean>0.0</mean>
          <stddev>0.001</stddev>
        </noise>
      </camera>
      <always_on>1</always_on>
      <visualize>1</visualize>
      <update_rate>10</update_rate>
      <plugin name="camera_plugin" filename="libgazebo_ros_openni_kinect.so">
        <robotNamespace>/l515_back</robotNamespace>
        <baseline>0.03</baseline>
        <alwaysOn>true</alwaysOn>
        <updateRate>10.0</updateRate>
        <cameraName>depth</cameraName>
        <imageTopicName>rgb_image_raw</imageTopicName>
        <cameraInfoTopicName>rgb_camera_info</cameraInfoTopicName>
        <depthImageTopicName>image_raw</depthImageTopicName>
        <depthImageCameraInfoTopicName>camera_info</depthImageCameraInfoTopicName>
        <pointCloudTopicName>pointcloud</pointCloudTopicName>
        <frameName>l515_camera_link_back</frameName>
        <pointCloudCutoff>0.25</pointCloudCutoff>
        <pointCloudCutoffMax>9.0</pointCloudCutoffMax>
        <hackBaseline>0.03</hackBaseline>
      </plugin>
    </sensor>
  </gazebo>

  <!--  Camera link -->
  <link name="t265_link">
    <inertial>
      <mass value="0.01"/>
      <inertia ixx="1.0e-5" ixy="0.0" ixz="0.0" iyy="1.0e-5" iyz="0.0" izz="1.0e-5"/>
    </inertial>
  </link>
  <joint name="cam_fixed_t265" type="fixed">
    <axis xyz="1 0 0"/>
    <origin rpy="0 0 0" xyz="0.285 0 0.1"/>
    <parent link="base_link"/>
    <child link="t265_link"/>
  </joint>
  <gazebo reference="t265_link">
    <sensor type="wideanglecamera" name="wideanglecamerat265">
      <camera name="tleft">
        <pose>0 0.032 0 0 0 0</pose>
        <horizontal_fov>3.141592</horizontal_fov>
        <image>
          <width>848</width>
          <height>800</height>
          <format>R8G8B8</format>
        </image>
        <clip>
          <near>0.02</near>
          <far>30000</far>
        </clip>
        <noise>
          <type>gaussian</type>
          <mean>0.0</mean>
          <stddev>0.001</stddev>
        </noise>
        <lens>
          <type>custom</type> 
          <custom_function>
            <c1>1.0</c1>  
            <c2>1.95</c2> 
            <f>6</f>      
            <fun>tan</fun> 
          </custom_function>
          <scale_to_hfov>true</scale_to_hfov>  
          <cutoff_angle>2.84488668</cutoff_angle>
          <env_texture_size>512</env_texture_size> 
        </lens>
      </camera>
      <plugin name="camera_controller" filename="libgazebo_ros_camera.so">
        <alwaysOn>true</alwaysOn>
        <updateRate>10.0</updateRate>
        <robotNamespace>/t265</robotNamespace>
        <cameraName>stereo_ir/left</cameraName>
        <imageTopicName>fisheye_image_raw</imageTopicName>
        <cameraInfoTopicName>camera_info</cameraInfoTopicName>
        <frameName>t265_camera_link</frameName>
        <hackBaseline>0</hackBaseline>
      </plugin>
    </sensor>
    <sensor type="wideanglecamera" name="wideanglecamerat265">
      <camera name="tright">
        <pose>0 -0.032 0 0 0 0</pose>
        <horizontal_fov>3.141592</horizontal_fov>
        <image>
          <width>848</width>
          <height>800</height>
          <format>R8G8B8</format>
        </image>
        <clip>
          <near>0.02</near>
          <far>30000</far>
        </clip>
        <noise>
          <type>gaussian</type>
          <mean>0.0</mean>
          <stddev>0.001</stddev>
        </noise>
        <lens>
          <type>custom</type> 
          <custom_function> 
            <c1>1.0</c1>  
            <c2>1.95</c2> 
            <f>6</f>    
            <fun>tan</fun>
          </custom_function>
          <scale_to_hfov>true</scale_to_hfov> 
          <cutoff_angle>2.84488668</cutoff_angle>
          <env_texture_size>512</env_texture_size> 
        </lens>
      </camera>
      <plugin name="camera_controller" filename="libgazebo_ros_camera.so">
        <alwaysOn>true</alwaysOn>
        <updateRate>10.0</updateRate>
        <robotNamespace>/t265</robotNamespace>
        <cameraName>stereo_ir/right</cameraName>
        <imageTopicName>fisheye_image_raw</imageTopicName>
        <cameraInfoTopicName>camera_info</cameraInfoTopicName>
        <frameName>t265_camera_link_right</frameName>
        <hackBaseline>0</hackBaseline>
      </plugin>
    </sensor>
  </gazebo>

<!--  Grasping plugin for real gripping -->
  <gazebo>
   <plugin name="gazebo_grasp_fix" filename="libgazebo_grasp_fix.so">
      <arm>
        <arm_name>KHNP_gripping_arm</arm_name>
<!--         <palm_link> left_inner_knuckle  </palm_link>
        <palm_link> right_inner_knuckle  </palm_link> -->
        <palm_link> left_outer_knuckle  </palm_link>
        <palm_link> right_outer_knuckle  </palm_link>
        <gripper_link> left_inner_finger </gripper_link>
        <gripper_link> right_inner_finger </gripper_link>
      </arm>
     <forces_angle_tolerance>90</forces_angle_tolerance>
     <update_rate>5</update_rate>
     <grip_count_threshold>2</grip_count_threshold>
     <max_grip_count>5</max_grip_count>
     <release_tolerance>0.01</release_tolerance>
     <disable_collisions_on_attach>false</disable_collisions_on_attach>
     <contact_topic>__default_topic__</contact_topic>
    </plugin>
  </gazebo>

</robot>
